<?xml version="1.0" ?>
<!-- =================================================================================== -->
<!-- |    This document was autogenerated by xacro from ar_description/urdf/ar.urdf.xacro | -->
<!-- |    EDITING THIS FILE BY HAND IS NOT RECOMMENDED                                 | -->
<!-- =================================================================================== -->
<robot name="ar_robot">
  <link name="world"/>
  <joint name="base_joint" type="fixed">
    <origin rpy="0 0 0" xyz="0 0 0"/>
    <parent link="world"/>
    <child link="base_link"/>
  </joint>
  <link name="base_link">
    <inertial>
      <origin rpy="0 0 0" xyz="-4.6941E-06 0.054174 0.038824"/>
      <mass value="0.7102"/>
      <inertia ixx="0.0039943" ixy="3.697E-07" ixz="-5.7364E-08" iyy="0.0014946" iyz="-0.00036051" izz="0.0042554"/>
    </inertial>
    <visual>
      <origin rpy="0 0 0" xyz="0 0 0"/>
      <geometry>
        <mesh filename="file:///home/yifei/src/ar4_ros_driver/install/ar_description/share/ar_description/meshes/ar4/base_link.STL"/>
      </geometry>
      <material name="">
        <color rgba="1 1 0 1"/>
      </material>
    </visual>
    <collision>
      <origin rpy="0 0 0" xyz="0 0 0"/>
      <geometry>
        <mesh filename="file:///home/yifei/src/ar4_ros_driver/install/ar_description/share/ar_description/meshes/ar4/base_link.STL"/>
      </geometry>
    </collision>
  </link>
  <link name="link_1">
    <inertial>
      <origin rpy="0 0 0" xyz="-0.022706 0.04294 -0.12205"/>
      <mass value="0.88065"/>
      <inertia ixx="0.0034" ixy="0.00042296" ixz="-0.00089231" iyy="0.0041778" iyz="0.0010848" izz="0.0027077"/>
    </inertial>
    <visual>
      <origin rpy="0 0 0" xyz="0 0 0"/>
      <geometry>
        <mesh filename="file:///home/yifei/src/ar4_ros_driver/install/ar_description/share/ar_description/meshes/ar4/link_1.STL"/>
      </geometry>
      <material name="">
        <color rgba="1 1 0 1"/>
      </material>
    </visual>
    <collision>
      <origin rpy="0 0 0" xyz="0 0 0"/>
      <geometry>
        <mesh filename="file:///home/yifei/src/ar4_ros_driver/install/ar_description/share/ar_description/meshes/ar4/link_1.STL"/>
      </geometry>
    </collision>
  </link>
  <joint name="joint_1" type="revolute">
    <origin rpy="3.141592653589793 0 0" xyz="0 0 0.003445"/>
    <parent link="base_link"/>
    <child link="link_1"/>
    <axis xyz="0 0 1"/>
    <limit effort="0" lower="-2.96705972839036" upper="2.96705972839036" velocity="0.5"/>
  </joint>
  <link name="link_2">
    <inertial>
      <origin rpy="0 0 0" xyz="0.064818 -0.11189 -0.038671"/>
      <mass value="0.57738"/>
      <inertia ixx="0.0047312" ixy="0.0022624" ixz="0.00032144" iyy="0.0020836" iyz="-0.00056569" izz="0.0056129"/>
    </inertial>
    <visual>
      <origin rpy="0 0 0" xyz="0 0 0"/>
      <geometry>
        <mesh filename="file:///home/yifei/src/ar4_ros_driver/install/ar_description/share/ar_description/meshes/ar4/link_2.STL"/>
      </geometry>
      <material name="">
        <color rgba="1 1 0 1"/>
      </material>
    </visual>
    <collision>
      <origin rpy="0 0 0" xyz="0 0 0"/>
      <geometry>
        <mesh filename="file:///home/yifei/src/ar4_ros_driver/install/ar_description/share/ar_description/meshes/ar4/link_2.STL"/>
      </geometry>
    </collision>
  </link>
  <joint name="joint_2" type="revolute">
    <origin rpy="1.5708 0.5236 -1.5708" xyz="0 0.064146 -0.16608"/>
    <parent link="link_1"/>
    <child link="link_2"/>
    <axis xyz="0 0 -1"/>
    <limit effort="0.5" lower="-0.7330382858376184" upper="1.5707963267948966" velocity="0"/>
  </joint>
  <link name="link_3">
    <inertial>
      <origin rpy="0 0 0" xyz="-0.00029765 -0.023661 -0.0019125"/>
      <mass value="0.1787"/>
      <inertia ixx="0.0001685" ixy="-2.7713E-05" ixz="5.6885E-06" iyy="0.00012865" iyz="2.9256E-05" izz="0.00020744"/>
    </inertial>
    <visual>
      <origin rpy="0 0 0" xyz="0 0 0"/>
      <geometry>
        <mesh filename="file:///home/yifei/src/ar4_ros_driver/install/ar_description/share/ar_description/meshes/ar4/link_3.STL"/>
      </geometry>
      <material name="">
        <color rgba="1 1 0 1"/>
      </material>
    </visual>
    <collision>
      <origin rpy="0 0 0" xyz="0 0 0"/>
      <geometry>
        <mesh filename="file:///home/yifei/src/ar4_ros_driver/install/ar_description/share/ar_description/meshes/ar4/link_3.STL"/>
      </geometry>
    </collision>
  </link>
  <joint name="joint_3" type="revolute">
    <origin rpy="0 0 -2.61799" xyz="0.1525 -0.26414 0"/>
    <parent link="link_2"/>
    <child link="link_3"/>
    <axis xyz="0 0 -1"/>
    <limit effort="0" lower="-1.5533430342749532" upper="0.9075712110370513" velocity="0.5"/>
  </joint>
  <link name="link_4">
    <inertial>
      <origin rpy="0 0 0" xyz="-0.0016798 -0.00057319 -0.074404"/>
      <mass value="0.34936"/>
      <inertia ixx="0.0030532" ixy="-1.8615E-05" ixz="-7.0047E-05" iyy="0.0031033" iyz="-2.3301E-05" izz="0.00022264"/>
    </inertial>
    <visual>
      <origin rpy="0 0 0" xyz="0 0 0"/>
      <geometry>
        <mesh filename="file:///home/yifei/src/ar4_ros_driver/install/ar_description/share/ar_description/meshes/ar4/link_4.STL"/>
      </geometry>
      <material name="">
        <color rgba="1 1 0 1"/>
      </material>
    </visual>
    <collision>
      <origin rpy="0 0 0" xyz="0 0 0"/>
      <geometry>
        <mesh filename="file:///home/yifei/src/ar4_ros_driver/install/ar_description/share/ar_description/meshes/ar4/link_4.STL"/>
      </geometry>
    </collision>
  </link>
  <joint name="joint_4" type="revolute">
    <origin rpy="1.5708 -1.2554 -1.5708" xyz="0 0 0.00675"/>
    <parent link="link_3"/>
    <child link="link_4"/>
    <axis xyz="0 0 -1"/>
    <limit effort="0" lower="-2.8797932657906435" upper="2.8797932657906435" velocity="0.5"/>
  </joint>
  <link name="link_5">
    <inertial>
      <origin rpy="0 0 0" xyz="0.0015066 -1.3102E-05 -0.012585"/>
      <mass value="0.11562"/>
      <inertia ixx="5.5035E-05" ixy="-1.019E-08" ixz="-2.6243E-06" iyy="8.2921E-05" iyz="1.4437E-08" izz="5.2518E-05"/>
    </inertial>
    <visual>
      <origin rpy="0 0 0" xyz="0 0 0"/>
      <geometry>
        <mesh filename="file:///home/yifei/src/ar4_ros_driver/install/ar_description/share/ar_description/meshes/ar4/link_5.STL"/>
      </geometry>
      <material name="">
        <color rgba="1 1 0 1"/>
      </material>
    </visual>
    <collision>
      <origin rpy="0 0 0" xyz="0 0 0"/>
      <geometry>
        <mesh filename="file:///home/yifei/src/ar4_ros_driver/install/ar_description/share/ar_description/meshes/ar4/link_5.STL"/>
      </geometry>
    </collision>
  </link>
  <joint name="joint_5" type="revolute">
    <origin rpy="3.141592653589793 0 -2.8262" xyz="0 0 -0.22225"/>
    <parent link="link_4"/>
    <child link="link_5"/>
    <axis xyz="1 0 0"/>
    <limit effort="0" lower="-1.8325957145940461" upper="1.8325957145940461" velocity="0.5"/>
  </joint>
  <link name="link_6">
    <inertial>
      <origin rpy="0 0 0" xyz="2.9287E-10 -1.6472E-09 0.0091432"/>
      <mass value="0.013863"/>
      <inertia ixx="1.3596E-06" ixy="3.0585E-13" ixz="5.7102E-14" iyy="1.7157E-06" iyz="6.3369E-09" izz="2.4332E-06"/>
    </inertial>
    <visual>
      <origin rpy="0 0 0" xyz="0 0 0"/>
      <geometry>
        <mesh filename="file:///home/yifei/src/ar4_ros_driver/install/ar_description/share/ar_description/meshes/ar4/link_6.STL"/>
      </geometry>
      <material name="">
        <color rgba="1 1 0 1"/>
      </material>
    </visual>
    <collision>
      <origin rpy="0 0 0" xyz="0 0 0"/>
      <geometry>
        <mesh filename="file:///home/yifei/src/ar4_ros_driver/install/ar_description/share/ar_description/meshes/ar4/link_6.STL"/>
      </geometry>
    </collision>
  </link>
  <joint name="joint_6" type="revolute">
    <origin rpy="0 0 3.1416" xyz="-0.000294 0 0.02117"/>
    <parent link="link_5"/>
    <child link="link_6"/>
    <axis xyz="0 0 1"/>
    <limit effort="0" lower="-2.705260340591211" upper="2.705260340591211" velocity="0.5"/>
  </joint>
  <!-- center of the end effector mounting surface on link_6 -->
  <link name="ee_link"/>
  <joint name="ee_joint" type="fixed">
    <parent link="link_6"/>
    <child link="ee_link"/>
    <origin rpy="0 0 0" xyz="0 0 0.016"/>
  </joint>
  <joint name="gripper_base_joint" type="fixed">
    <origin rpy="-1.5708 0.0 0.0" xyz="0.0 0.0 0.0"/>
    <parent link="ee_link"/>
    <child link="gripper_base_link"/>
  </joint>
  <link name="gripper_base_link">
    <visual>
      <geometry>
        <mesh filename="file:///home/yifei/src/ar4_ros_driver/install/ar_description/share/ar_description/meshes/ar4_gripper/gripper_base_link.stl"/>
      </geometry>
    </visual>
    <collision>
      <geometry>
        <mesh filename="file:///home/yifei/src/ar4_ros_driver/install/ar_description/share/ar_description/meshes/ar4_gripper/gripper_base_link.stl"/>
      </geometry>
    </collision>
    <inertial>
      <origin xyz="-0.00073621 -0.02341392 -0.00435302"/>
      <mass value="0.08"/>
      <inertia ixx="0.00002375" ixy="0.00000002" ixz="-0.00000017" iyy="0.00004082" iyz="-0.00000029" izz="0.00004254"/>
    </inertial>
  </link>
  <link name="gripper_jaw1_link">
    <visual>
      <geometry>
        <mesh filename="file:///home/yifei/src/ar4_ros_driver/install/ar_description/share/ar_description/meshes/ar4_gripper/gripper_jaw1_link.stl"/>
      </geometry>
    </visual>
    <collision>
      <geometry>
        <mesh filename="file:///home/yifei/src/ar4_ros_driver/install/ar_description/share/ar_description/meshes/ar4_gripper/gripper_jaw1_link.stl"/>
      </geometry>
    </collision>
    <inertial>
      <origin xyz="-0.00435839 -0.00469536 0.00757141"/>
      <mass value="0.01"/>
      <inertia ixx="0.00000123" ixy="-0.00000004" ixz="0.00000012" iyy="0.00000115" iyz="0.00000016" izz="0.00000102"/>
    </inertial>
  </link>
  <link name="gripper_jaw2_link">
    <visual>
      <geometry>
        <mesh filename="file:///home/yifei/src/ar4_ros_driver/install/ar_description/share/ar_description/meshes/ar4_gripper/gripper_jaw2_link.stl"/>
      </geometry>
    </visual>
    <collision>
      <geometry>
        <mesh filename="file:///home/yifei/src/ar4_ros_driver/install/ar_description/share/ar_description/meshes/ar4_gripper/gripper_jaw2_link.stl"/>
      </geometry>
    </collision>
    <inertial>
      <origin xyz="-0.00423971 -0.00491236 0.00814582"/>
      <mass value="0.01"/>
      <inertia ixx="0.00000118" ixy="-0.00000004" ixz="0.00000013" iyy="0.00000110" iyz="0.00000013" izz="0.00000101"/>
    </inertial>
  </link>
  <joint name="gripper_jaw1_joint" type="prismatic">
    <origin rpy="0.0 0.0 0.0" xyz="0.0 -0.036 -0.0155"/>
    <parent link="gripper_base_link"/>
    <child link="gripper_jaw1_link"/>
    <axis xyz="1 0 0"/>
    <limit effort="0" lower="-0.014" upper="0" velocity="0.1"/>
  </joint>
  <joint name="gripper_jaw2_joint" type="prismatic">
    <origin rpy="0.0 -3.141592653589793 0.0" xyz="0.0 -0.036 0.0097"/>
    <parent link="gripper_base_link"/>
    <child link="gripper_jaw2_link"/>
    <axis xyz="1 0 0"/>
    <limit effort="0" lower="-0.014" upper="0" velocity="0.1"/>
    <mimic joint="gripper_jaw1_joint" multiplier="1" offset="0"/>
  </joint>
</robot>
